---
layout: post
title: Rust the book -- 08 Error Handling
date: 22-03-01 12:57:40 +0800
categories: rust
---

[TOC]

<a name="Top"></a>

# Rust 学习 - 08

## 第8章 错误处理(Error Handling)

Rust将错误分为两类：

1.   可恢复的错误(recoverable)：可以重复尝试产生错误的操作，例如文件未找到；
2.   不可恢复的错误(unrecoverable)：一般是bug的症状，例如访问数组边界外的元素；

Rust没有exception，Rust使用Result\<T, E\>枚举来表示可恢复错误，用`panic!`宏来产生不可恢复错误。

### 1. 用panic!处理不可恢复错误

当`panic!`宏执行时，程序开始释放资源，释放程序栈帧并清理数据，然后退出。也可以使用abort来立即停止程序，而不释放资源，留给操作系统释放。

-   在Cargo.toml中的`[profile]`段添加`panic = 'abort'`来将`panic!`的操作转换为abort

-   如果只想在release模式中转换，可以采用以下写法：

    ```toml
    [profile.release]
    panic = 'abort'
    ```

在代码中使用`panic!`宏：

```rust
fn main() {
    panic!("crash and burn!");
}
```

运行程序将得到：

```sh
thread 'main' panicked at 'crash and burn', src/main.rs:2:5
note: run with `RUST_BACKTRACE=1` environment variable to display a backtrace
```

#### 1.1 使用panic!获取调用回溯(backtrace)

通过`RUST_BACKTRACE=1 cargo run`来获取调用回溯，同时必须有Debug标志。Debug标志在没有使用`--release`选项运行程序或编译时是默认设置的。



### 2. 用Result处理可恢复错误

Result是一个Rust自定义的枚举类型：

```rust
enum Result<T, E> {
    Ok(T),
    Err(E),
}
```

其中`T`是操作成功时的返回值类型，`E`是操作失败时的返回值类型。下面的代码通过文件IO来演示对Result的解析：

```rust
use std::fs::File;

fn main() {
    let f = File::open("hello.txt");

    let f = match f {
        Ok(file) => file,
        Err(error) => panic!("Problem opening the file: {:?}", error),
    };
}
```

上面的代码中，`File::open`的返回值类型是`Result<std::fs::File, std::io::Error>`，通过match语句对Result进行解析。

#### 2.1 match不同类型的错误

```rust
use std::fs::File;
use std::io::ErrorKind;

fn main() {
    let f = File::open("hello.txt");

    let f = match f {
        Ok(file) => file,
        Err(error) => match error.kind() { // .kind()方法获取Error的ErrorKind枚举
            ErrorKind::NotFound => match File::create("hello.txt") { // 因为File::create也可能出错，所以需要对它的返回值进行处理
                Ok(fc) => fc,
                Err(e) => panic!("Problem creating the file: {:?}", e),
            },
            other_error => {
                panic!("Problem opening the file: {:?}", other_error)
            }
        },
    };
}
```

上面的代码用了很多match，在第13章将会介绍closure，使用closure来处理Result会使代码更简洁：

```rust
use std::fs::File;
use std::io::ErrorKind;

fn main() {
    let f = File::open("hello.txt").unwrap_or_else(|error| {
        if error.kind() == ErrorKind::NotFound {
            File::create("hello.txt").unwrap_or_else(|error| {
                panic!("Problem creating the file: {:?}", error);
            })
        } else {
            panic!("Problem opening the file: {:?}", error);
        }
    });
}
```

看完第13章再回来看这里的代码吧！再看看标准库文档中的`unwrap_or_else`方法，以及其他类似的方法，可以干掉多重match的嵌套结构。

#### 2.2 出现错误时panic的简便方法：unwrap和expect

使用match有时会显得过于啰嗦，可以使用Result的成员函数`unwrap`，当Result返回Err时，会自动调用`panic!`宏：

```rust
use std::fs::File;
fn main() {
    let f = File::open("hello.txt").unwrap();
}
```

上面的代码当文件`hello.txt`不存在时就会直接panic。

另一个成员函数`expect`和`unwrap`类似，不过可以自己定义报错的字符串：

```rust
use std::fs::File;

fn main() {
    let f = File::open("hello.txt").expect("Failed to open hello.txt");
}
```

#### 2.3 传播错误

当一个函数内部存在可能出现的错误时，一种方法是将错误返回给调用函数的代码，让它来决定如何处理这个错误，这叫做传播错误。

```rust
use std::fs::File;
use std::io::{self, Read};

fn read_username_from_file() -> Result<String, io::Error> {
    let f = File::open("hello.txt");

    let mut f = match f {
        Ok(file) => file,
        Err(e) => return Err(e),
    };

    let mut s = String::new();

    match f.read_to_string(&mut s) {
        Ok(_) => Ok(s),
        Err(e) => Err(e),
    }
}
```

上面的代码分别在打开文件和读取字符串时可能出现错误，并且都通过match语句进行解析，第一个Result在出现错误时直接利用return关键字返回错误，第二个Result则在函数末尾直接返回，如果出错就直接返回错误。

上面的错误传播方式在Rust中机器常见，所以Rust提供了`?`操作符来使错误传播更加简单。

#### 2.4 错误传播的简便方法：？操作符

用`?`操作符重新实现上面的函数：

```rust
use std::fs::File;
use std::io;
use std::io::Read;

fn read_username_from_file() -> Result<String, io::Error> {
    let mut f = File::open("hello.txt")?;
    let mut s = String::new();
    f.read_to_string(&mut s)?;
    Ok(s)
}
```

在`Result`值后面的`?`操作符的功能是：当返回值是Ok，则把Ok内的值返回给变量，如果是Err，就使用return来返回错误。

和上面用match操作的唯一不同点是：使用？操作符返回时，Err类型会转换为函数返回值中定义的错误类型

还可以把返回Result的方法连起来，并在它们之间使用?操作符，以进一步简化代码：

```rust
use std::fs::File;
use std::io;
use std::io::Read;

fn read_username_from_file() -> Result<String, io::Error> {
    let mut s = String::new();
    File::open("hello.txt")?.read_to_string(&mut s)?;
    Ok(s)
}
```

本例中，还有更简单的方法来重写这个读取字符串的函数：

```rust
use std::fs;
use std::io;

fn read_username_from_file() -> Result<String, io::Error> {
    fs::read_to_string("hello.txt")
}
```

因为从文件读取字符串是一个非常常用的操作，所以Rust提供了`fs::read_to_string`函数实现。

#### 2.5 ？操作符还可以用在哪

`?`操作符必须用在返回`Result Option`或其他实现了FromResidual方法的类型的函数中。当`?`操作符被用在`Option`类型上时，如果Option的值是`None`，就提前进行返回；如果是`Some`，表达式的值就变为`Some`内存储的值。

```rust
fn last_char_of_first_line(text: &str) -> Option<char> {
    text.lines().next()?.chars().last()
}
```

`Result`和`Option`都可以通过`?`操作符返回，但是不能混着用，二者不存在自动类型转换。如果实在需要，可以使用`Result`的`ok`方法和`Option`的`ok_or`方法。

main函数在返回`None`时，Rust默认让其返回0，除此之外，main函数还能返回`Result<(), E>`。

```rust
use std::error::Error;
use std::fs::File;

fn main() -> Result<(), Box<dyn Error>> {
    let f = File::open("hello.txt")?;

    Ok(())
}
```

`Box<dyn Error>`类型是一个特性对象，这会在第17章讨论。现在可以简单地把它当做一个任意类型的错误。此时，就可以在main函数中使用`?`操作符了。

main函数可以返回的类型必须实现特性：`std::process::Termination`



### 3. To panic! or Not to panic!

本节讨论何时应该使用panic来终止程序，给出了几个适合使用panic的例子

#### 3.1 Examples, Prototype Code and Tests

1.   编写示例：添加详尽的错误处理会使示例过于冗长，而此时使用`unwrap`是在提醒使用你编写的示例的人，此处应该添加错误处理；
2.   原型代码：当还没有决定好如何处理错误时，使用`unwrap expect`可以作为标记，在未来确定好如何处理错误时再进行错误处理；
3.   测试代码：当一个方法在测试中出错，则整个测试应该停止，因为`panic!`在测试中被标记为failure。

#### 3.2 你拥有比编译器更多的信息

当通过严格的代码审计，确定错误不可能发生时，则可以直接使用`unwrap`，例如：

```rust
use std::net::IpAddr;
let home: IpAddr = "127.0.0.1".parse().unwrap();
```

字符串字面值`127.0.0.1`一定是一个有效的IP地址，所以后面的`parse`方法不可能出错，而编译器是不知道这个信息的，所以此时可以`unwrap`。

如果需要`parse`的地址是用户输入的，那么这里就可能出现错误。

#### 3.3 错误处理指南

当代码可能从一个坏的状态返回时，`panic!`是建议的。

#### 3.4 自建类型进行状态验证

有时需要对某些数据进行验证，这种验证可以通过一个自建类型进行，例如当我们保证一个数在一定范围之内，可以用`if`判断：

```rust
fn main() {
    // --snip--
    let num: i32 = match input_num.trim().parse().expect("Error parse num");
    if num < 1 || num > 100 {
        panic!("The number should be between 1 ~ 100.");
    }
    do_some_work(&num);
}
```

更好的方法是建立一个类型来进行判断，这样客户代码在获得数的时候就可以保证它可用，而不必再次检查：

```rust
pub struct NumValid {
    value: i32, // private
}

impl NumValid {
    pub fn new(value: i32) -> NumValid {
        if value < 1 || value > 100 {
            panic!("The number should be between 1 ~ 100.");
        }
        NumValid { value }
    }
    
    pub fn value(&self) -> i32 {
        self.value
    }
}

fn main() {
    let num: i32 = match input_num.trim().parse().expect("Error parse num");
    let num: NumValid = NumValid::new(num);
    do_some_work(&num.value());
}
```



### 总结

Rust 的错误处理功能旨在帮助您编写更健壮的代码。 `panic!` 宏表示您的程序处于无法处理的状态，并让您告诉进程停止，而不是尝试使用无效或不正确的值继续。`Result` 枚举使用 Rust 的类型系统来指示操作可能会以您的代码可以从中恢复的方式失败。 您可以使用 `Result` 告诉调用您的代码的代码它也需要处理潜在的成功或失败。 使用`panic!` 并在适当的情况下导致您的代码在面对不可避免的问题时更加可靠。




---

[Return to Top](#Top)

